<?xml version="1.0"?>

<robot name="virtual_robot" xmlns:xacro="http://www.ros.org/wiki/xacro">

  <!-- Global namespace -->
  <xacro:arg name="robot_name" default="car_1" />
  <xacro:arg name="robot_skin" default="Blue" />

  <!-- inertial parameter macros -->

  <xacro:macro name="chassis_inertial_params">
    <origin xyz="0.1477 0 0" rpy="0 0 0" />
    <mass value="4.0" />
    <inertia ixx="0.010609" ixy="0"          ixz="0"
                            iyy="0.050409"   iyz="0"
                                             izz="0.05865" />
  </xacro:macro>

  <xacro:macro name="left_wheels_inertial_params">
    <origin xyz="0 0 -0.0225" rpy="0 0 0" />
    <mass value="0.34055" />
    <inertia ixx="0.00026046" ixy="0"          ixz="0"
                              iyy="0.00026046" iyz="0"
                                               izz="0.00041226" />
  </xacro:macro>

  <xacro:macro name="right_wheels_inertial_params">
    <origin xyz="0 0 0.0225" rpy="0 0 0" />
    <mass value="0.34055" />
    <inertia ixx="0.00026046" ixy="0"          ixz="0"
                              iyy="0.00026046" iyz="0"
                                               izz="0.00041226" />
  </xacro:macro>

  <xacro:macro name="steering_hinge_inertial_params">
    <origin xyz="0 0 0" rpy="0 0 0" />
    <mass value="0.100" />
    <inertia ixx="4E-06" ixy="0"           ixz="0"
                              iyy="4E-06"  iyz="0"
                                                izz="4E-06" />
  </xacro:macro>

  <xacro:macro name="hokuyo_inertial_params">
    <origin xyz="0 0 0" rpy="0 0 0" />
    <mass value="0.130" />
    <inertia ixx="4E-06" ixy="0"           ixz="0"
                              iyy="4E-06"  iyz="0"
                                                izz="4E-06" />
  </xacro:macro>


  <!-- geometry macros -->

  <xacro:macro name="chassis_geometry">
    <origin xyz="0.46 -0.135 -0.180" rpy="1.57 0 3.14" />
    <geometry>
      <mesh filename="package://description/meshes/chassis.stl" scale="0.000990 0.0009375 0.0009375"/>
    </geometry>
  </xacro:macro>


  <xacro:macro name="left_rear_wheel_geometry">
    <origin xyz="0 0 0" rpy="0 0 0" />
    <geometry>
      <mesh filename="package://description/meshes/left_wheel.stl" />
    </geometry>
  </xacro:macro>

  <xacro:macro name="right_rear_wheel_geometry">
    <origin xyz="0 0 0" rpy="0 0 0" />
    <geometry>
      <mesh filename="package://description/meshes/right_wheel.stl" />
    </geometry>
  </xacro:macro>

  <xacro:macro name="left_front_wheel_geometry">
    <origin xyz="0 0 0" rpy="0 0 0" />
    <geometry>
      <mesh filename="package://description/meshes/left_wheel.stl" />
    </geometry>
  </xacro:macro>

  <xacro:macro name="right_front_wheel_geometry">
    <origin xyz="0 0 0" rpy="0 0 0" />
    <geometry>
      <mesh filename="package://description/meshes/right_wheel.stl" />
    </geometry>
  </xacro:macro>

  <xacro:macro name="left_steering_hinge_geometry">
    <origin xyz="0 0 0" rpy="0 0 0" />
    <geometry>
      <mesh filename="package://description/meshes/hinge.stl" />
    </geometry>
  </xacro:macro>

  <xacro:macro name="right_steering_hinge_geometry">
    <origin xyz="0 0 0" rpy="0 0 0" />
    <geometry>
      <mesh filename="package://description/meshes/hinge.stl" />
    </geometry>
  </xacro:macro>

  <xacro:macro name="left_wheels_collision_geometry">
    <origin xyz="0 0 -0.0225" rpy="0 0 0" />
    <geometry>
      <cylinder length="0.045" radius="0.05" />
    </geometry>
  </xacro:macro>

  <xacro:macro name="right_wheels_collision_geometry">
    <origin xyz="0 0 0.0225" rpy="0 0 0" />
    <geometry>
      <cylinder length="0.045" radius="0.05" />
    </geometry>
  </xacro:macro>

  <!-- transmission macros -->

  <xacro:macro name="wheel_transmission" params="name">
    <transmission name="${name}_transmission" type="SimpleTransmission">
      <type>transmission_interface/SimpleTransmission</type>
      <joint name="${name}_joint">
        <hardwareInterface>hardware_interface/EffortJointInterface</hardwareInterface>
      </joint>
      <actuator name="${name}_motor">
        <hardwareInterface>hardware_interface/EffortJointInterface</hardwareInterface>
        <mechanicalReduction>1</mechanicalReduction>
      </actuator>
    </transmission>
  </xacro:macro>

  <xacro:macro name="steering_hinge_transmission" params="name">
    <transmission name="${name}_transmission" type="SimpleTransmission">
      <type>transmission_interface/SimpleTransmission</type>
      <joint name="${name}_joint">
        <hardwareInterface>hardware_interface/EffortJointInterface</hardwareInterface>
      </joint>
      <actuator name="${name}_motor">
        <hardwareInterface>hardware_interface/EffortJointInterface</hardwareInterface>
        <mechanicalReduction>1</mechanicalReduction>
      </actuator>
    </transmission>
  </xacro:macro>

  <!-- Add chassis and it's inertia link -->

  <link name="$(arg robot_name)_base_link"/>

  <link name="$(arg robot_name)_chassis">
    <visual>
      <xacro:chassis_geometry/>
      <material name="red" />
    </visual>
    <!-- ALC231105 BEGIN - FIXME - Front wheels steering will self-collide with the chassis,
                                   so cancel chassis collision for now -->
    <!-- <collision>
      <xacro:chassis_geometry/>
    </collision> -->
    <!-- ALC231105 END -->
  </link>

  <joint name="$(arg robot_name)_base_link_joint" type="fixed">
    <origin xyz="0 0 0.05" rpy="0 0 0" />
    <parent link="$(arg robot_name)_base_link" />
    <child link="$(arg robot_name)_chassis" />
  </joint>

  <link name="$(arg robot_name)_chassis_inertia">
    <inertial>
      <xacro:chassis_inertial_params />
    </inertial>
  </link>

  <joint name="$(arg robot_name)_chassis_inertia_joint" type="fixed">
    <origin xyz="0 0 0" rpy="0 0 0" />
    <parent link="$(arg robot_name)_chassis" />
    <child link="$(arg robot_name)_chassis_inertia" />
  </joint>

  <!-- Add the left rear wheel with its joints and tranmissions -->

  <link name="$(arg robot_name)_left_rear_wheel">
    <inertial>
      <xacro:left_wheels_inertial_params />
    </inertial>
    <visual>
      <xacro:left_rear_wheel_geometry />
      <material name="black" />
    </visual>
    <collision>
      <xacro:left_wheels_collision_geometry />
    </collision>
  </link>

  <joint name="$(arg robot_name)_left_rear_wheel_joint" type="continuous">
    <origin xyz="0 0.1 0" rpy="1.5708 0 0" />
    <parent link="$(arg robot_name)_chassis" />
    <child link="$(arg robot_name)_left_rear_wheel" />
    <axis xyz="0 0 -1" />
    <limit effort="10" velocity="100" />
  </joint>

  <xacro:wheel_transmission name="$(arg robot_name)_left_rear_wheel" />

  <!-- Add the right rear wheel with its joints and tranmissions -->

  <link name="$(arg robot_name)_right_rear_wheel">
    <inertial>
      <xacro:right_wheels_inertial_params />
    </inertial>
    <visual>
      <xacro:right_rear_wheel_geometry />
      <material name="black" />
    </visual>
    <collision>
      <xacro:right_wheels_collision_geometry />
    </collision>
  </link>

  <joint name="$(arg robot_name)_right_rear_wheel_joint" type="continuous">
    <origin xyz="0 -0.1 0" rpy="1.5708 0 0" />
    <parent link="$(arg robot_name)_chassis" />
    <child link="$(arg robot_name)_right_rear_wheel" />
    <axis xyz="0 0 -1" />
    <limit effort="10" velocity="100" />
  </joint>

  <xacro:wheel_transmission name="$(arg robot_name)_right_rear_wheel" />

  <!-- Add the left steering hinge with its joints and tranmissions -->

  <link name="$(arg robot_name)_left_steering_hinge">
    <inertial>
      <xacro:steering_hinge_inertial_params />
    </inertial>
    <visual>
      <xacro:left_steering_hinge_geometry />
      <material name="grey" />
    </visual>
  </link>

  <joint name="$(arg robot_name)_left_steering_hinge_joint" type="revolute">
    <origin xyz="0.325 0.1 0" rpy="0 1.5708 0" />
    <parent link="$(arg robot_name)_chassis" />
    <child link="$(arg robot_name)_left_steering_hinge" />
    <axis xyz="-1 0 0" />
    <limit lower="-1.0" upper="1.0" effort="10" velocity="100" />
  </joint>

  <xacro:steering_hinge_transmission name="$(arg robot_name)_left_steering_hinge" />

  <!-- Add the right steering hinge with its joints and tranmissions -->

  <link name="$(arg robot_name)_right_steering_hinge">
    <inertial>
      <xacro:steering_hinge_inertial_params />
    </inertial>
    <visual>
      <xacro:right_steering_hinge_geometry />
      <material name="grey" />
    </visual>
  </link>

  <joint name="$(arg robot_name)_right_steering_hinge_joint" type="revolute">
    <origin xyz="0.325 -0.1 0" rpy="0 1.5708 0" />
    <parent link="$(arg robot_name)_chassis" />
    <child link="$(arg robot_name)_right_steering_hinge" />
    <axis xyz="-1 0 0" />
    <limit lower="-1.0" upper="1.0" effort="10" velocity="100" />
  </joint>

  <xacro:steering_hinge_transmission name="$(arg robot_name)_right_steering_hinge" />

  <!-- Add the left front wheel with its joints and tranmissions -->

  <link name="$(arg robot_name)_left_front_wheel">
    <inertial>
      <xacro:left_wheels_inertial_params />
    </inertial>
    <visual>
      <xacro:left_front_wheel_geometry />
      <material name="black" />
    </visual>
    <collision>
      <xacro:left_wheels_collision_geometry />
    </collision>
  </link>

  <joint name="$(arg robot_name)_left_front_wheel_joint" type="continuous">
    <origin xyz="0 0 0" rpy="1.5708 0 0" />
    <parent link="$(arg robot_name)_left_steering_hinge" />
    <child link="$(arg robot_name)_left_front_wheel" />
    <axis xyz="0 0 -1" />
    <limit effort="10" velocity="100" />
  </joint>

  <xacro:wheel_transmission name="$(arg robot_name)_left_front_wheel" />

  <!-- Add the left front wheel with its joints and tranmissions -->

  <link name="$(arg robot_name)_right_front_wheel">
    <inertial>
      <xacro:right_wheels_inertial_params />
    </inertial>
    <visual>
      <xacro:right_front_wheel_geometry />
      <material name="black" />
    </visual>
    <collision>
      <xacro:right_wheels_collision_geometry />
    </collision>
  </link>

  <joint name="$(arg robot_name)_right_front_wheel_joint" type="continuous">
    <origin xyz="0 0 0" rpy="1.5708 0 0" />
    <parent link="$(arg robot_name)_right_steering_hinge" />
    <child link="$(arg robot_name)_right_front_wheel" />
    <axis xyz="0 0 -1" />
    <limit effort="10" velocity="100"/>
  </joint>

  <xacro:wheel_transmission name="$(arg robot_name)_right_front_wheel" />

  <!-- Add Hokuyo laser scanner -->
  <!-- ALC231105 - Removed, see f1tenth-dev/simulator branch for original content. -->

  <!-- camera class (spawn parameters) -->
  <!-- ALC231105 - Removed, see f1tenth-dev/simulator branch for original content. -->


  <!-- Gazebo references -->

  <gazebo reference="$(arg robot_name)_chassis">
    <mu1 value="0.0"/>
    <mu2 value="0.0"/>
    <kp  value="10000000.0" />
    <kd  value="1.0" />
    <material>Gazebo/$(arg robot_skin)</material>
  </gazebo>

  <gazebo reference="$(arg robot_name)_left_rear_wheel">
    <mu1 value="1.0"/>
    <mu2 value="1.0"/>
    <kp  value="10000000.0" />
    <kd  value="1.0" />
    <fdir1 value="1 0 0"/>
    <material>Gazebo/Black</material>
  </gazebo>

  <gazebo reference="$(arg robot_name)_right_rear_wheel">
    <mu1 value="1.0"/>
    <mu2 value="1.0"/>
    <kp  value="10000000.0" />
    <kd  value="1.0" />
    <fdir1 value="1 0 0"/>
    <material>Gazebo/Black</material>
  </gazebo>

  <gazebo reference="$(arg robot_name)_left_front_wheel">
    <mu1 value="1.0"/>
    <mu2 value="1.0"/>
    <kp  value="10000000.0" />
    <kd  value="1.0" />
    <fdir1 value="0 0 1"/>
    <material>Gazebo/Black</material>
  </gazebo>

  <gazebo reference="$(arg robot_name)_right_front_wheel">
    <mu1 value="1.0"/>
    <mu2 value="1.0"/>
    <kp  value="10000000.0" />
    <kd  value="1.0" />
    <fdir1 value="0 0 1"/>
    <material>Gazebo/Black</material>
  </gazebo>

  <!-- Gazebo plugins -->

  <gazebo>
    <plugin name="gazebo_ros_control" filename="libgazebo_ros_control.so">
      <robotNamespace>/$(arg robot_name)</robotNamespace>
      <robotSimType>gazebo_ros_control/DefaultRobotHWSim</robotSimType>
    </plugin>
  </gazebo>

  <!-- Odometry (cheap hack) -->
  <gazebo>
    <plugin name="p3d_base_controller" filename="libgazebo_ros_p3d.so">
      <alwaysOn>true</alwaysOn>
      <updateRate>50.0</updateRate>
      <bodyName>$(arg robot_name)_base_link</bodyName>
      <topicName>/$(arg robot_name)/ground_truth</topicName>
      <gaussianNoise>0.01</gaussianNoise>
      <frameName>world</frameName>
      <xyzOffsets>0 0 0</xyzOffsets>
      <rpyOffsets>0 0 0</rpyOffsets>
    </plugin>
  </gazebo>

  <!-- hokuyo -->
  <!-- ALC231105 - Removed, see f1tenth-dev/simulator branch for original content. -->

  <!-- camera object -->
  <!-- ALC231105 - Removed, see f1tenth-dev/simulator branch for original content. -->

  <material name="black">
    <color rgba="0.0 0.0 0.0 1.0"/>
  </material>

  <material name="blue">
    <color rgba="0.0 0.0 0.8 1.0"/>
  </material>

  <material name="green">
    <color rgba="0.0 0.8 0.0 1.0"/>
  </material>

  <material name="grey">
    <color rgba="0.2 0.2 0.2 1.0"/>
  </material>

  <material name="orange">
    <color rgba="${255/255} ${108/255} ${10/255} 1.0"/>
  </material>

  <material name="brown">
    <color rgba="${222/255} ${207/255} ${195/255} 1.0"/>
  </material>

  <material name="red">
    <color rgba="0.8 0.0 0.0 1.0"/>
  </material>

  <material name="white">
    <color rgba="1.0 1.0 1.0 1.0"/>
  </material>

</robot>
